Workbook
Name Slicer_Department_Name: #N/A
Name Slicer_Eligible_Bonus: #N/A
Name Slicer_Perf_Score: #N/A
Name Slicer_Salary: #N/A
Name Slicer_Year_of_Service: #N/A

Sheet Raw_Employee_Data
A1: Emp ID | B1: First_Name | C1: Last_Name | D1: Dept Code | E1: Hire Date | F1: Salary | G1: Perf_Score | H1: Employment Status
A2: EMP127 | B2: Emily | C2: Brown | D2: IT02 | E2: 43093 | F2: 50361 | G2: 52 | H2: active
A3: EMP046 | B3: Richard | C3: Hernandez | D3: MKT04 | E3: 44659 | F3: 112673 | H3: ACTIVE
A4: EMP134 | B4: Emily | C4: Gonzalez | D4: IT02 | E4: 42431 | F4: $114,425 | G4: 54 | H4: LEFT
A5: EMP139 | B5: John | C5: Martinez | D5: FIN03 | E5: 45110 | F5: 103831 | G5: 70 | H5: active
A6: EMP112 | B6: Thomas | C6: Smith | D6: IT02 | E6: 44977 | F6: 73785 | G6: 40 | H6: Left
A7: EMP030 | B7: Emily | C7: Johnson | D7: OPS06 | E7: 02-Mar-20 | F7: 115882 | G7: 49 | H7: ACTIVE
A8: EMP096 | B8: John | C8: Wilson | D8: OPS06 | E8: 45272 | F8: 59980 | G8: 70 | H8: Left
A9: EMP098 | B9: Jessica | C9: Smith | D9: OPS06 | E9: 44174 | F9: 68728 | G9: 45 | H9: ACTIVE
A10: EMP095 | C10: Rodriguez | D10: FIN03 | E10: 43107 | F10: 102139 | G10: 79 | H10: active
A11: EMP140 | B11: Michael | C11: Martinez | D11: SAL05 | E11: 42676 | F11: 94998 | G11: 58 | H11: Active
A12: EMP020 | B12: Emily | C12: Miller | D12: sal05 | E12: 43911 | F12: $118,635 | G12: 49 | H12: Active
A13: EMP057 | B13: Emily | C13: Hernandez | D13: IT02 | E13: 42425 | F13: 76918 | G13: 62 | H13: Actv
A14: EMP016 | B14: Jane | C14: Williams | D14: mkt04 | E14: 17-Jun-21 | F14: 61408 | G14: 48 | H14: ACTIVE
A15: EMP070 | B15: Jane | C15: Miller | D15: MKT04 | E15: 44001 | F15: 99990 | G15: 54 | H15: Actv
A16: EMP025 | B16: Robert | C16: Jones | D16: MKT04 | E16: 43820 | F16: 80385 | H16: active
A17: EMP031 | B17: Thomas | C17: Rodriguez | D17: SAL05 | E17: 45169 | F17: 65290 | G17: 77 | H17: active
A18: EMP126 | B18: Emily | C18: Davis | D18: IT02 | E18: 42337 | F18: 105765 | G18: 42 | H18: Active
A19: EMP109 | B19: James | C19: Martinez | D19: SAL05 | E19: 42899 | F19: 102921 | G19: 49 | H19: ACTIVE
A20: EMP057 | B20: Emily | C20: Hernandez | D20: IT02 | E20: 42425 | F20: 76918 | G20: 62 | H20: Actv
A21: EMP066 | B21: Ashley | C21: Lopez | D21: MKT04 | E21: 43235 | F21: 73984 | G21: 93 | H21: Actv
A22: EMP120 | B22: Amanda | C22: Gonzalez | D22: IT02 | E22: 42575 | G22: 75 | H22: Actv
A23: EMP019 | B23: Michael | C23: Hernandez | D23: FIN03 | E23: 43076 | F23: 118527 | G23: 50 | H23: Actv
A24: EMP013 | B24: Richard | C24: Hernandez | D24: MKT04 | E24: 44353 | F24: 107871 | G24: 88 | H24: active
A25: EMP010 | B25: Michael | C25: Rodriguez | D25: IT02 | E25: 44815 | F25: 93956 | G25: 50 | H25: LEFT
A26: EMP032 | B26: Jessica | C26: Johnson | D26: FIN03 | E26: 42565 | F26: 100851 | G26: 64 | H26: ACTIVE
A27: EMP082 | B27: Ashley | C27: Williams | D27: SAL05 | E27: 44728 | F27: 68655 | G27: 32 | H27: active
A28: EMP052 | C28: Williams | D28: SAL05 | E28: 45134 | F28: 81205 | G28: 59 | H28: Actv
A29: EMP129 | B29: John | C29: Wilson | D29: SAL05 | E29: 09/24/2019 | F29: $77,610 | G29: 88 | H29: Actv
A30: EMP146 | B30: Thomas | C30: Rodriguez | D30: it02 | E30: 44765 | F30: $50,873 | G30: 90 | H30: Active
A31: EMP099 | B31: Michael | C31: Wilson | D31: fin03 | E31: 13-May-18 | F31: 85312 | G31: 66 | H31: active
A32: EMP015 | B32: John | C32: Rodriguez | D32: SAL05 | E32: 42202 | G32: 68 | H32: active
A33: EMP076 | B33: Thomas | C33: Hernandez | D33: OPS06 | E33: 05-Aug-15 | F33: 97055 | G33: 80 | H33: Actv
A34: EMP137 | B34: Michael | C34: Johnson | D34: IT02 | E34: 45195 | F34: 66069 | G34: 72 | H34: Actv
A35: EMP056 | B35: Sarah | C35: Brown | D35: it02 | E35: 10-Jun-19 | F35: 90157 | G35: 58 | H35: active
A36: EMP125 | B36: Jane | C36: Martinez | D36: HR01 | E36: 44578 | F36: 59899 | G36: 78 | H36: Actv
A37: EMP085 | B37: Emily | C37: Jones | D37: FIN03 | E37: 03-Jul-17 | F37: 113389 | G37: 30 | H37: ACTIVE
A38: EMP106 | C38: Brown | D38: IT02 | E38: 01-Sep-15 | F38: 102691 | G38: 52 | H38: Active
A39: EMP043 | B39: John | C39: Wilson | D39: OPS06 | E39: 03-Aug-22 | F39: 111845 | G39: 98 | H39: active
A40: EMP068 | B40: Melissa | C40: Brown | D40: SAL05 | E40: 06/29/2022 | F40: 69219 | G40: 93 | H40: Actv
...

Sheet Lookup_Departments
A1: Dept_Code | B1: Department_Name
A2: HR01 | B2: Human Resources
A3: IT02 | B3: Information Technology
A4: FIN03 | B4: Finance
A5: MKT04 | B5: Marketing
A6: SAL05 | B6: Sales
A7: OPS06 | B7: Operations

Sheet Lookup_Performance
A1: Min_Score | B1: Max_Score | C1: Performance_Band | D1: Bonus_Percentage
A2: 0 | B2: 49 | C2: Needs Improvement | D2: 0
A3: 50 | B3: 69 | C3: Developing | D3: 0.02
A4: 70 | B4: 84 | C4: Achieving | D4: 0.05
A5: 85 | B5: 94 | C5: Exceeding | D5: 0.08
A6: 95 | B6: 100 | C6: Outstanding | D6: 0.12

Sheet Cleaned Employee Data
B1: Emp ID | C1: First_Name | D1: Last_Name | E1: Full Name | F1: Dept Code | G1: Department Name | H1: Hire Date | I1: Year of Service | J1: Salary | K1: Eligible Bonus | L1: Perf_Score | M1: Performance Band | N1: Employment Status
B2: EMP127 | C2: Emily | D2: Brown | E2: =TRIM(Table1[[#This Row],[First_Name]]&" "&Table1[[#This Row],[Last_Name]]) -> Emily Brown | F2: IT02 | G2: =VLOOKUP(Table1[[#This Row],[Dept Code]],Lookup_Departments!$A:$B,2,FALSE) -> Information Technology | H2: 43093 | I2: =ROUND((TODAY()-Table1[[#This Row],[Hire Date]])/365.25,1) -> 8.5 | J2: 50361 | K2: =J2*VLOOKUP(L2,Lookup_Performance!$A:$D,4,TRUE) -> 1007.22 | L2: 52 | M2: =VLOOKUP(Table1[[#This Row],[Perf_Score]],Lookup_Performance!$A:$D,3,TRUE) -> Developing | N2: ACTIVE
B3: EMP046 | C3: Richard | D3: Hernandez | E3: =TRIM(Table1[[#This Row],[First_Name]]&" "&Table1[[#This Row],[Last_Name]]) -> Richard Hernandez | F3: MKT04 | G3: =VLOOKUP(Table1[[#This Row],[Dept Code]],Lookup_Departments!$A:$B,2,FALSE) -> Marketing | H3: 44659 | I3: =ROUND((TODAY()-Table1[[#This Row],[Hire Date]])/365.25,1) -> 4.3 | J3: 112673 | K3: =J3*VLOOKUP(L3,Lookup_Performance!$A:$D,4,TRUE) -> 5633.65 | L3: 74 | M3: =VLOOKUP(Table1[[#This Row],[Perf_Score]],Lookup_Performance!$A:$D,3,TRUE) -> Achieving | N3: ACTIVE
B4: EMP134 | C4: Emily | D4: Gonzalez | E4: =TRIM(Table1[[#This Row],[First_Name]]&" "&Table1[[#This Row],[Last_Name]]) -> Emily Gonzalez | F4: IT02 | G4: =VLOOKUP(Table1[[#This Row],[Dept Code]],Lookup_Departments!$A:$B,2,FALSE) -> Information Technology | H4: 42431 | I4: =ROUND((TODAY()-Table1[[#This Row],[Hire Date]])/365.25,1) -> 10.4 | J4: 114425 | K4: =J4*VLOOKUP(L4,Lookup_Performance!$A:$D,4,TRUE) -> 2288.5 | L4: 54 | M4: =VLOOKUP(Table1[[#This Row],[Perf_Score]],Lookup_Performance!$A:$D,3,TRUE) -> Developing | N4: LEFT
B5: EMP139 | C5: John | D5: Martinez | E5: =TRIM(Table1[[#This Row],[First_Name]]&" "&Table1[[#This Row],[Last_Name]]) -> John Martinez | F5: FIN03 | G5: =VLOOKUP(Table1[[#This Row],[Dept Code]],Lookup_Departments!$A:$B,2,FALSE) -> Finance | H5: 45110 | I5: =ROUND((TODAY()-Table1[[#This Row],[Hire Date]])/365.25,1) -> 3 | J5: 103831 | K5: =J5*VLOOKUP(L5,Lookup_Performance!$A:$D,4,TRUE) -> 5191.55 | L5: 70 | M5: =VLOOKUP(Table1[[#This Row],[Perf_Score]],Lookup_Performance!$A:$D,3,TRUE) -> Achieving | N5: ACTIVE
B6: EMP112 | C6: Thomas | D6: Smith | E6: =TRIM(Table1[[#This Row],[First_Name]]&" "&Table1[[#This Row],[Last_Name]]) -> Thomas Smith | F6: IT02 | G6: =VLOOKUP(Table1[[#This Row],[Dept Code]],Lookup_Departments!$A:$B,2,FALSE) -> Information Technology | H6: 44977 | I6: =ROUND((TODAY()-Table1[[#This Row],[Hire Date]])/365.25,1) -> 3.4 | J6: 73785 | K6: =J6*VLOOKUP(L6,Lookup_Performance!$A:$D,4,TRUE) -> 0 | L6: 40 | M6: =VLOOKUP(Table1[[#This Row],[Perf_Score]],Lookup_Performance!$A:$D,3,TRUE) -> Needs Improvement | N6: LEFT
B7: EMP030 | C7: Emily | D7: Johnson | E7: =TRIM(Table1[[#This Row],[First_Name]]&" "&Table1[[#This Row],[Last_Name]]) -> Emily Johnson | F7: OPS06 | G7: =VLOOKUP(Table1[[#This Row],[Dept Code]],Lookup_Departments!$A:$B,2,FALSE) -> Operations | H7: 43892 | I7: =ROUND((TODAY()-Table1[[#This Row],[Hire Date]])/365.25,1) -> 6.4 | J7: 115882 | K7: =J7*VLOOKUP(L7,Lookup_Performance!$A:$D,4,TRUE) -> 0 | L7: 49 | M7: =VLOOKUP(Table1[[#This Row],[Perf_Score]],Lookup_Performance!$A:$D,3,TRUE) -> Needs Improvement | N7: ACTIVE
B8: EMP096 | C8: John | D8: Wilson | E8: =TRIM(Table1[[#This Row],[First_Name]]&" "&Table1[[#This Row],[Last_Name]]) -> John Wilson | F8: OPS06 | G8: =VLOOKUP(Table1[[#This Row],[Dept Code]],Lookup_Departments!$A:$B,2,FALSE) -> Operations | H8: 45272 | I8: =ROUND((TODAY()-Table1[[#This Row],[Hire Date]])/365.25,1) -> 2.6 | J8: 59980 | K8: =J8*VLOOKUP(L8,Lookup_Performance!$A:$D,4,TRUE) -> 2999 | L8: 70 | M8: =VLOOKUP(Table1[[#This Row],[Perf_Score]],Lookup_Performance!$A:$D,3,TRUE) -> Achieving | N8: LEFT
B9: EMP098 | C9: Jessica | D9: Smith | E9: =TRIM(Table1[[#This Row],[First_Name]]&" "&Table1[[#This Row],[Last_Name]]) -> Jessica Smith | F9: OPS06 | G9: =VLOOKUP(Table1[[#This Row],[Dept Code]],Lookup_Departments!$A:$B,2,FALSE) -> Operations | H9: 44174 | I9: =ROUND((TODAY()-Table1[[#This Row],[Hire Date]])/365.25,1) -> 5.6 | J9: 68728 | K9: =J9*VLOOKUP(L9,Lookup_Performance!$A:$D,4,TRUE) -> 0 | L9: 45 | M9: =VLOOKUP(Table1[[#This Row],[Perf_Score]],Lookup_Performance!$A:$D,3,TRUE) -> Needs Improvement | N9: ACTIVE
B10: EMP095 | C10: Unknown | D10: Rodriguez | E10: =TRIM(Table1[[#This Row],[First_Name]]&" "&Table1[[#This Row],[Last_Name]]) -> Unknown Rodriguez | F10: FIN03 | G10: =VLOOKUP(Table1[[#This Row],[Dept Code]],Lookup_Departments!$A:$B,2,FALSE) -> Finance | H10: 43107 | I10: =ROUND((TODAY()-Table1[[#This Row],[Hire Date]])/365.25,1) -> 8.5 | J10: 102139 | K10: =J10*VLOOKUP(L10,Lookup_Performance!$A:$D,4,TRUE) -> 5106.95 | L10: 79 | M10: =VLOOKUP(Table1[[#This Row],[Perf_Score]],Lookup_Performance!$A:$D,3,TRUE) -> Achieving | N10: ACTIVE
B11: EMP140 | C11: Michael | D11: Martinez | E11: =TRIM(Table1[[#This Row],[First_Name]]&" "&Table1[[#This Row],[Last_Name]]) -> Michael Martinez | F11: SAL05 | G11: =VLOOKUP(Table1[[#This Row],[Dept Code]],Lookup_Departments!$A:$B,2,FALSE) -> Sales | H11: 42676 | I11: =ROUND((TODAY()-Table1[[#This Row],[Hire Date]])/365.25,1) -> 9.7 | J11: 94998 | K11: =J11*VLOOKUP(L11,Lookup_Performance!$A:$D,4,TRUE) -> 1899.96 | L11: 58 | M11: =VLOOKUP(Table1[[#This Row],[Perf_Score]],Lookup_Performance!$A:$D,3,TRUE) -> Developing | N11: ACTIVE
B12: EMP020 | C12: Emily | D12: Miller | E12: =TRIM(Table1[[#This Row],[First_Name]]&" "&Table1[[#This Row],[Last_Name]]) -> Emily Miller | F12: SAL05 | G12: =VLOOKUP(Table1[[#This Row],[Dept Code]],Lookup_Departments!$A:$B,2,FALSE) -> Sales | H12: 43911 | I12: =ROUND((TODAY()-Table1[[#This Row],[Hire Date]])/365.25,1) -> 6.3 | J12: 118635 | K12: =J12*VLOOKUP(L12,Lookup_Performance!$A:$D,4,TRUE) -> 0 | L12: 49 | M12: =VLOOKUP(Table1[[#This Row],[Perf_Score]],Lookup_Performance!$A:$D,3,TRUE) -> Needs Improvement | N12: ACTIVE
B13: EMP057 | C13: Emily | D13: Hernandez | E13: =TRIM(Table1[[#This Row],[First_Name]]&" "&Table1[[#This Row],[Last_Name]]) -> Emily Hernandez | F13: IT02 | G13: =VLOOKUP(Table1[[#This Row],[Dept Code]],Lookup_Departments!$A:$B,2,FALSE) -> Information Technology | H13: 42425 | I13: =ROUND((TODAY()-Table1[[#This Row],[Hire Date]])/365.25,1) -> 10.4 | J13: 76918 | K13: =J13*VLOOKUP(L13,Lookup_Performance!$A:$D,4,TRUE) -> 1538.36 | L13: 62 | M13: =VLOOKUP(Table1[[#This Row],[Perf_Score]],Lookup_Performance!$A:$D,3,TRUE) -> Developing | N13: ACTIVE
... B151: EMP103 | C151: Amanda | D151: Brown | E151: =TRIM(Table1[[#This Row],[First_Name]]&" "&Table1[[#This Row],[Last_Name]]) -> Amanda Brown | F151: IT02 | G151: =VLOOKUP(Table1[[#This Row],[Dept Code]],Lookup_Departments!$A:$B,2,FALSE) -> Information Technology | H151: 44848 | I151: =ROUND((TODAY()-Table1[[#This Row],[Hire Date]])/365.25,1) -> 3.7 | J151: 118634 | K151: =J151*VLOOKUP(L151,Lookup_Performance!$A:$D,4,TRUE) -> 9490.72 | L151: 91 | M151: =VLOOKUP(Table1[[#This Row],[Perf_Score]],Lookup_Performance!$A:$D,3,TRUE) -> Exceeding | N151: ACTIVE

Sheet Analysis
A2: Count of Emp ID | C2: Sum of Salary | E2: Sum of Eligible Bonus | G2: Average of Year of Service
A3: 150 | C3: 12432919 | E3: 497972.02 | G3: 6.944
B5: =GETPIVOTDATA("Emp ID",$A$2) -> 150 | F5: =GETPIVOTDATA("Eligible Bonus",$E$2) -> 497972.02 | R5: Row Labels | S5: Average of Perf_Score
R6: ACTIVE | S6: 67.939655
R7: LEFT | S7: 66.083333
A8: Row Labels | B8: Sum of Salary | E8: Row Labels | F8: Sum of Salary | H8: Row Labels | I8: Sum of Salary | L8: Row Labels | M8: Count of Emp ID | N8: Average of Perf_Score | R8: RESIGNED | S8: 76.4
A9: Finance | B9: 0.11964286 | E9: Achieving | F9: 0.30283633 | H9: ACTIVE | I9: 0.77503059 | L9: ACTIVE | M9: 116 | N9: 67.939655 | R9: Grand Total | S9: 68.206667
A10: Human Resources | B10: 0.12400471 | E10: Developing | F10: 0.29770812 | H10: LEFT | I10: 0.15277406 | L10: LEFT | M10: 24 | N10: 66.083333
A11: Information Technology | B11: 0.2301579 | E11: Exceeding | F11: 0.14493998 | H11: RESIGNED | I11: 0.072195355 | L11: RESIGNED | M11: 10 | N11: 76.4
A12: Marketing | B12: 0.1304725 | E12: Needs Improvement | F12: 0.19316952 | H12: Grand Total | I12: 1 | L12: Grand Total | M12: 150 | N12: 68.206667
A13: Operations | B13: 0.18431762 | E13: Outstanding | F13: 0.061346052
A14: Sales | B14: 0.21140442 | E14: Grand Total | F14: 1
A15: Grand Total | B15: 1
A18: Row Labels | B18: Sum of Salary | O18: Row Labels | P18: Count of Emp ID | Q18: Sum of Eligible Bonus
A19: EMP011 | B19: 103891 | O19: Achieving | P19: 47 | Q19: 0.3780473
A20: Grand Total | B20: 103891 | O20: Developing | P20: 43 | Q20: 0.14865819
O21: Exceeding | P21: 22 | Q21: 0.28949852
O22: Needs Improvement | P22: 28 | Q22: 0
O23: Outstanding | P23: 10 | Q23: 0.18379599
O24: Grand Total | P24: 150 | Q24: 1
J27: Row Labels | K27: Sum of Eligible Bonus | M27: Row Labels | N27: Sum of Eligible Bonus | P27: Count of Emp ID | Q27: Column Labels
J28: Achieving | K28: 0.3780473 | M28: Finance | N28: 0.099560113 | P28: Row Labels | Q28: LEFT | R28: RESIGNED | S28: Grand Total
D29: Average of Salary | J29: Developing | K29: 0.14865819 | M29: Human Resources | N29: 0.15453798 | P29: Finance | Q29: 3 | S29: 3
D30: 82886.127 | J30: Exceeding | K30: 0.28949852 | M30: Information Technology | N30: 0.20781022 | P30: Human Resources | Q30: 2 | R30: 1 | S30: 3
J31: Needs Improvement | K31: 0 | M31: Marketing | N31: 0.15775688 | P31: Information Technology | Q31: 6 | R31: 2 | S31: 8
E32: =GETPIVOTDATA("Salary",$D$29) -> 82886.127 | J32: Outstanding | K32: 0.18379599 | M32: Operations | N32: 0.20270189 | P32: Marketing | Q32: 3 | S32: 3
J33: Grand Total | K33: 1 | M33: Sales | N33: 0.17763291 | P33: Operations | Q33: 6 | R33: 5 | S33: 11
M34: Grand Total | N34: 1 | P34: Sales | Q34: 4 | R34: 2 | S34: 6
P35: Grand Total | Q35: 24 | R35: 10 | S35: 34
G36: Row Labels | H36: Sum of Salary
G37: Achieving | H37: 0.30283633
G38: Developing | H38: 0.29770812 | L38: Row Labels | M38: Count of Perf_Score | P38: Row Labels | Q38: Sum of Salary | R38: Count of Emp ID
G39: Exceeding | H39: 0.14493998 | L39: ACTIVE | M39: 116 | P39: Finance | Q39: 1487510 | R39: 17
G40: Needs Improvement | H40: 0.19316952 | L40: LEFT | M40: 24 | P40: Human Resources | Q40: 1541740.5 | R40: 18
G41: Outstanding | H41: 0.061346052 | L41: RESIGNED | M41: 10 | P41: Information Technology | Q41: 2861534.5 | R41: 36
B42: =(24+10)/150 -> 0.22666667 | G42: Grand Total | H42: 1 | L42: Grand Total | M42: 150 | P42: Marketing | Q42: 1622154 | R42: 19
P43: Operations | Q43: 2291606 | R43: 29
F44: Row Labels | G44: Count of Emp ID | P44: Sales | Q44: 2628374 | R44: 31
F45: ACTIVE | G45: 116 | P45: Grand Total | Q45: 12432919 | R45: 150
F46: LEFT | G46: 24
...

Sheet Chart

Sheet Dashboard
